Running 24 test cases...
boost/boost_test.cpp(21): error: in "my_suite1/my_test1": check 2 == 1 has failed
boost/boost_test.cpp(28): error: in "my_suite1/my_test2": check i == 2 has failed [0 != 2]
boost/boost_test.cpp(47): error: in "my_suite2/my_test4": check i == 1 has failed [0 != 1]
boost/boost_test.cpp(56): error: in "my_suite2/internal_suite/my_test5": check i == 1 has failed [0 != 1]
Hello from cout
unknown location(0): fatal error: in "testException": std::runtime_error: runtime exception text
boost/boost_test.cpp(82): last checkpoint: "testException" test entry
unknown location(0): fatal error: in "testAssertExceptionFail": std::runtime_error: runtime exception text
boost/boost_test.cpp(94): last checkpoint
boost/boost_test.cpp(99): fatal error: in "testFatal": bfail
boost/boost_test.cpp(104): error: in "testError": berror
boost/boost_test.cpp(126): error: in "test_case_arity1/_0": check (var <= 4 && var >= 1) has failed
Failure occurred in a following context:
    var = 0; 
boost/boost_test.cpp(150): error: in "checkpointTest": check 1 != 1 has failed [1 == 1]
unknown location(0): fatal error: in "checkpointTest": std::runtime_error: Undefined Behaviour ahead!
boost/boost_test.cpp(150): last checkpoint
boost/boost_test.cpp(157): error: in "contextsTest": Intentionally failed test
Failure occurred in a following context:
    This is contextsTest
boost/boost_test.cpp(161): error: in "contextsTest": check 1 != 1 has failed [1 == 1]
Failure occurred in a following context:
    Alpha
boost/boost_test.cpp(164): error: in "contextsTest": check 3 != 3 has failed [3 == 3]
Failure occurred in a following context:
    Alpha
    Beta
boost/boost_test.cpp(169): error: in "contextsTest": check 5 != 5 has failed [5 == 5]
boost/boost_test.cpp(136): error: in "dependencySkippedTest": check 1 != 1 has failed [1 == 1]
