Running 13 test cases...
boost/boost_test.cpp(11): error: in "my_suite1/my_test1": check 2 == 1 has failed
boost/boost_test.cpp(18): error: in "my_suite1/my_test2": check i == 2 has failed [0 != 2]
boost/boost_test.cpp(37): error: in "my_suite2/my_test4": check i == 1 has failed [0 != 1]
boost/boost_test.cpp(46): error: in "my_suite2/internal_suite/my_test5": check i == 1 has failed [0 != 1]
Hello from cout
unknown location(0): fatal error: in "testException": std::runtime_error: runtime exception text
boost/boost_test.cpp(72): last checkpoint: "testException" entry.
unknown location(0): fatal error: in "testAssertExceptionFail": std::runtime_error: runtime exception text
boost/boost_test.cpp(84): last checkpoint
boost/boost_test.cpp(89): fatal error: in "testFatal": bfail
boost/boost_test.cpp(94): error: in "testError": berror
