Running 14 test cases...
boost/boost_test.cpp(15): error in "my_test1": check 2 == 1 failed
boost/boost_test.cpp(22): error in "my_test2": check i == 2 failed [0 != 2]
boost/boost_test.cpp(41): error in "my_test4": check i == 1 failed [0 != 1]
boost/boost_test.cpp(50): error in "my_test5": check i == 1 failed [0 != 1]
Hello from cout
unknown location(0): fatal error in "testException": std::runtime_error: runtime exception text
boost/boost_test.cpp(50): last checkpoint
unknown location(0): fatal error in "testAssertExceptionFail": std::runtime_error: runtime exception text
boost/boost_test.cpp(88): last checkpoint
boost/boost_test.cpp(93): fatal error in "testFatal": bfail
boost/boost_test.cpp(98): error in "testError": berror
